<?xml version="1.0" ?>
<!-- =================================================================================== -->
<!-- |    This document was autogenerated by xacro from kuka.urdf.xacro                | -->
<!-- |    EDITING THIS FILE BY HAND IS NOT RECOMMENDED                                 | -->
<!-- =================================================================================== -->
<robot name="kr6_r700_sixx_robot">
  <!--
    Base KUKA robot series xacro macro

    NOTE this is NOT a URDF. It cannot dirrectly be loaded by consumers
    expecting a flattened '.urdf' file. See the top-level '.xacro' for that
    (but note that .xacro must still be processed by the xacro command).

    This file models the base kinematic chain of KUKA robot, which then gets
    parameterized by various configuration files to convert it into a kr6_r700_sixx,
    kr6_r900_sixx, kr6_r1100_2

    NOTE the default kinematic parameters (i,e., link lengths, frame locations,
    offsets etc) do not correspond to any particular robot. They are defaults
    only. There WILL be non-zero offsets between the Forward Kinematics results
    in TF (i.e., robot_state_publisher) and the values reported by the Teach Pendant

    For accurate (and robot-specific) transforms, the 'kinematics_parameters_file'
    parameter MUST point to '.yaml' file contaiinig the appropriate values for the
    targeted robot.

    Author: Shahwaz Khan
   -->
  <!--
    NOTE the macros defined in this file are NOT part of the public API of this
         package. Users CANNOT rely on this file being available, or stored in
         this location. Nor can they rely on the existence of the two macros.
         The macros store the defined properties in the scope of the caller.
         However, users MUST NOT rely on these properties, their contents or their
         names. They are subject to change without notice.

    Author: Shahwaz Khan
  -->
  <!--
    NOTE the macro defined in this file is NOT part of the public API of this
          package. Users CANNOT rely on this file being available, or stored in
          this location. Nor can they rely on the existence of the macro.
  -->
  <!-- create link fixed to the "world" -->
  <link name="world"/>
  <ros2_control name="kr6_r700_sixx_robot" type="system">
    <hardware>
      <plugin>mock_components/GenericSystem</plugin>
      <param name="mock_sensor_commands">false</param>
      <param name="state_following_offset">0.0</param>
    </hardware>
    <joint name="joint_1">
      <command_interface name="position"/>
      <state_interface name="position">
        <param name="initial_value">0.0</param>
      </state_interface>
    </joint>
    <joint name="joint_2">
      <command_interface name="position"/>
      <state_interface name="position">
        <param name="initial_value">-1.57</param>
      </state_interface>
    </joint>
    <joint name="joint_3">
      <command_interface name="position"/>
      <state_interface name="position">
        <param name="initial_value">0.0</param>
      </state_interface>
    </joint>
    <joint name="joint_4">
      <command_interface name="position"/>
      <state_interface name="position">
        <param name="initial_value">-1.57</param>
      </state_interface>
    </joint>
    <joint name="joint_5">
      <command_interface name="position"/>
      <state_interface name="position">
        <param name="initial_value">0.0</param>
      </state_interface>
    </joint>
    <joint name="joint_6">
      <command_interface name="position"/>
      <state_interface name="position">
        <param name="initial_value">0.0</param>
      </state_interface>
    </joint>
  </ros2_control>
  <!-- Links -main serial chain -->
  <link name="base_link"/>
  <link name="base_link_inertia">
    <visual>
      <origin rpy="0 0 0" xyz="0 0 0"/>
      <geometry>
        <mesh filename="package://kuka_robot_descriptions/meshes/kr6_r700_sixx/visual/base_link.dae"/>
      </geometry>
      <material name="KukaPedestal">
        <color rgba="0.5058823529411764 0.47058823529411764 0.38823529411764707 1.0"/>
      </material>
    </visual>
    <collision>
      <origin rpy="0 0 0" xyz="0 0 0"/>
      <geometry>
        <mesh filename="package://kuka_robot_descriptions/meshes/kr6_r700_sixx/collision/base_link.stl"/>
      </geometry>
    </collision>
    <inertial>
      <mass value="0.0"/>
      <origin rpy="0 0 0" xyz="0 0 0"/>
      <inertia ixx="0.0" ixy="0.0" ixz="0.0" iyy="0.0" iyz="0.0" izz="0.0"/>
    </inertial>
  </link>
  <!-- Link-1 -->
  <link name="link_1">
    <visual>
      <origin rpy="0 0 0" xyz="0 0 0"/>
      <geometry>
        <mesh filename="package://kuka_robot_descriptions/meshes/kr6_r700_sixx/visual/link_1.dae"/>
      </geometry>
      <material name="KukaOrange">
        <color rgba="0.9647058823529412 0.47058823529411764 0.1568627450980392 1.0"/>
      </material>
    </visual>
    <collision>
      <geometry>
        <mesh filename="package://kuka_robot_descriptions/meshes/kr6_r700_sixx/collision/link_1.stl"/>
      </geometry>
    </collision>
    <inertial>
      <mass value="0.0"/>
      <origin rpy="0 0 0" xyz="0 0 0"/>
      <inertia ixx="0.0" ixy="0.0" ixz="0.0" iyy="0.0" iyz="0.0" izz="0.0"/>
    </inertial>
  </link>
  <!-- Link-2 -->
  <link name="link_2">
    <visual>
      <origin rpy="0 0 0" xyz="0 0 0"/>
      <geometry>
        <mesh filename="package://kuka_robot_descriptions/meshes/kr6_r700_sixx/visual/link_2.dae"/>
      </geometry>
      <material name="KukaOrange">
        <color rgba="0.9647058823529412 0.47058823529411764 0.1568627450980392 1.0"/>
      </material>
    </visual>
    <collision>
      <geometry>
        <mesh filename="package://kuka_robot_descriptions/meshes/kr6_r700_sixx/collision/link_2.stl"/>
      </geometry>
    </collision>
    <inertial>
      <mass value="0.0"/>
      <origin rpy="0 0 0" xyz="0 0 0"/>
      <inertia ixx="0.0" ixy="0.0" ixz="0.0" iyy="0.0" iyz="0.0" izz="0.0"/>
    </inertial>
  </link>
  <!-- Link-3 -->
  <link name="link_3">
    <visual>
      <origin rpy="0 0 0" xyz="0 0 0"/>
      <geometry>
        <mesh filename="package://kuka_robot_descriptions/meshes/kr6_r700_sixx/visual/link_3.dae"/>
      </geometry>
      <material name="KukaOrange">
        <color rgba="0.9647058823529412 0.47058823529411764 0.1568627450980392 1.0"/>
      </material>
    </visual>
    <collision>
      <geometry>
        <mesh filename="package://kuka_robot_descriptions/meshes/kr6_r700_sixx/collision/link_3.stl"/>
      </geometry>
    </collision>
    <inertial>
      <mass value="0.0"/>
      <origin rpy="0 0 0" xyz="0 0 0"/>
      <inertia ixx="0.0" ixy="0.0" ixz="0.0" iyy="0.0" iyz="0.0" izz="0.0"/>
    </inertial>
  </link>
  <!-- Link-4 -->
  <link name="link_4">
    <visual>
      <origin rpy="0 0 0" xyz="0 0 0"/>
      <geometry>
        <mesh filename="package://kuka_robot_descriptions/meshes/kr6_r700_sixx/visual/link_4.dae"/>
      </geometry>
      <material name="KukaOrange">
        <color rgba="0.9647058823529412 0.47058823529411764 0.1568627450980392 1.0"/>
      </material>
    </visual>
    <collision>
      <geometry>
        <mesh filename="package://kuka_robot_descriptions/meshes/kr6_r700_sixx/collision/link_4.stl"/>
      </geometry>
    </collision>
    <inertial>
      <mass value="0.0"/>
      <origin rpy="0 0 0" xyz="0 0 0"/>
      <inertia ixx="0.0" ixy="0.0" ixz="0.0" iyy="0.0" iyz="0.0" izz="0.0"/>
    </inertial>
  </link>
  <!-- Link-5 -->
  <link name="link_5">
    <visual>
      <origin rpy="0 0 0" xyz="0 0 0"/>
      <geometry>
        <mesh filename="package://kuka_robot_descriptions/meshes/kr6_r700_sixx/visual/link_5.dae"/>
      </geometry>
      <material name="KukaOrange">
        <color rgba="0.9647058823529412 0.47058823529411764 0.1568627450980392 1.0"/>
      </material>
    </visual>
    <collision>
      <geometry>
        <mesh filename="package://kuka_robot_descriptions/meshes/kr6_r700_sixx/collision/link_5.stl"/>
      </geometry>
    </collision>
    <inertial>
      <mass value="0.0"/>
      <origin rpy="0 0 0" xyz="0 0 0"/>
      <inertia ixx="0.0" ixy="0.0" ixz="0.0" iyy="0.0" iyz="0.0" izz="0.0"/>
    </inertial>
  </link>
  <!-- Link-6 -->
  <link name="link_6">
    <visual>
      <origin rpy="0 0 0" xyz="0 0 0"/>
      <geometry>
        <mesh filename="package://kuka_robot_descriptions/meshes/kr6_r700_sixx/visual/link_6.dae"/>
      </geometry>
      <material name="KukaOrange">
        <color rgba="0.9647058823529412 0.47058823529411764 0.1568627450980392 1.0"/>
      </material>
    </visual>
    <collision>
      <geometry>
        <mesh filename="package://kuka_robot_descriptions/meshes/kr6_r700_sixx/collision/link_6.stl"/>
      </geometry>
    </collision>
    <inertial>
      <mass value="0.0"/>
      <origin rpy="0 0 0" xyz="0 0 0"/>
      <inertia ixx="0.0" ixy="0.0" ixz="0.0" iyy="0.0" iyz="0.0" izz="0.0"/>
    </inertial>
  </link>
  <!-- base_joint fixes base_link to the environment -->
  <joint name="base_joint" type="fixed">
    <parent link="world"/>
    <child link="base_link"/>
    <origin rpy="0 0 0" xyz="0 0 0"/>
  </joint>
  <!-- ROS base_link to KUKA $ROBROOT coordinate system transform -->
  <joint name="base_link-base_link_inertia" type="fixed">
    <parent link="base_link"/>
    <child link="base_link_inertia"/>
    <origin rpy="0 0 0" xyz="0 0 0"/>
  </joint>
  <!-- joints - main serial chain -->
  <!-- Joint-1 -->
  <joint name="joint_1" type="revolute">
    <parent link="base_link_inertia"/>
    <child link="link_1"/>
    <origin rpy="0.0 0.0 0.0" xyz="0.0 0.0 0.4"/>
    <axis xyz="0 0 -1"/>
    <limit effort="0.0" lower="-2.9670597283903604" upper="2.9670597283903604" velocity="6.283185307179586"/>
  </joint>
  <!-- Joint-2 -->
  <joint name="joint_2" type="revolute">
    <parent link="link_1"/>
    <child link="link_2"/>
    <origin rpy="0.0 0.0 0.0" xyz="0.025 0.0 0.0"/>
    <axis xyz="0 1 0"/>
    <limit effort="0.0" lower="-3.3161255787892263" upper="0.7853981633974483" velocity="5.235987755982989"/>
  </joint>
  <!-- Joint-3 -->
  <joint name="joint_3" type="revolute">
    <parent link="link_2"/>
    <child link="link_3"/>
    <origin rpy="0.0 0.0 0.0" xyz="0.0315 0.0 0.0"/>
    <axis xyz="0 1 0"/>
    <limit effort="0.0" lower="-2.0943951023931953" upper="2.722713633111154" velocity="6.283185307179586"/>
  </joint>
  <!-- Joint-4 -->
  <joint name="joint_4" type="revolute">
    <parent link="link_3"/>
    <child link="link_4"/>
    <origin rpy="0.0 0.0 0.0" xyz="0.0 0.0 0.035"/>
    <axis xyz="0 1 0"/>
    <limit effort="0.0" lower="-3.2288591161895095" upper="3.2288591161895095" velocity="6.649704450098396"/>
  </joint>
  <!-- Joint-5 -->
  <joint name="joint_5" type="revolute">
    <parent link="link_4"/>
    <child link="link_5"/>
    <origin rpy="0.0 0.0 0.0" xyz="0.365 0.0 0.0"/>
    <axis xyz="0 1 0"/>
    <limit effort="0.0" lower="-2.0943951023931953" upper="2.0943951023931953" velocity="6.771877497737998"/>
  </joint>
  <!-- Joint-6 -->
  <joint name="joint_6" type="revolute">
    <parent link="link_5"/>
    <child link="link_6"/>
    <origin rpy="0.0 0.0 0.0" xyz="0.08 0.0 0.0"/>
    <axis xyz="0 1 0"/>
    <limit effort="0.0" lower="-6.1086523819801535" upper="6.1086523819801535" velocity="10.733774899765127"/>
  </joint>
  <!-- ROS-Industrial 'flange' frame - attachment point for EEF models -->
  <link name="flange"/>
  <joint name="flange-joint_6" type="fixed">
    <parent link="link_6"/>
    <child link="flange"/>
    <origin rpy="0 0 0 " xyz="0 0 0"/>
  </joint>
  <!-- This frame corresponds to the $TOOL coordinate system in KUKA KRC controllers -->
  <link name="tool0"/>
  <joint name="flange-tool0" type="fixed">
    <parent link="flange"/>
    <child link="tool0"/>
    <origin rpy="0 1.5707963267948966 0" xyz="0 0 0"/>
  </joint>
</robot>
